<?xml version='1.0'?>
<sdf version='1.11'>
  <model name='Waterwitch'>
    <link name='rov_body'>
      <pose>0 0 0 0 0 0</pose>
      <inertial>
        <mass>6.9075069579159996</mass>
        <pose>0 0 0 0 0 0</pose>
        <inertia>
          <ixx>0.11811426857338</ixx>
          <ixy>4.2870375665810001e-06</ixy>
          <ixz>0.00021516428040740999</ixz>
          <iyy>0.1134262861325</iyy>
          <iyz>0.00013587201593204999</iyz>
          <izz>0.18179128145473999</izz>
        </inertia>
      </inertial>
      <self_collide>false</self_collide>
      <enable_wind>false</enable_wind>
      <kinematic>false</kinematic>
      <gravity>true</gravity>
      <visual name='rov_body_visual'>
        <pose>0 0 0 0 0 0</pose>
        <geometry>
          <mesh>
            <uri>waterwitch_no_enclosure_cover.stl</uri>
            <scale>1 1 1</scale>
          </mesh>
        </geometry>
        <material>
          <shader type='pixel'/>
          <ambient>0.200000003 0.200000003 0.600000024 1</ambient>
          <diffuse>0.200000003 0.200000003 0.600000024 1</diffuse>
          <specular>0.200000003 0.200000003 0.600000024 1</specular>
          <emissive>0.200000003 0.200000003 0.600000024 1</emissive>
        </material>
        <transparency>0</transparency>
        <cast_shadows>false</cast_shadows>
      </visual>
      <collision name='rov_body_collision'>
        <max_contacts>10</max_contacts>
        <pose>0 0 0 0 0 0</pose>
        <geometry>
          <mesh>
            <uri>waterwitch.stl</uri>
            <scale>1 1 1</scale>
          </mesh>
        </geometry>
      </collision>
    </link>
    <link name='for_star_propeller'>
      <pose>-0.13500000000000001 -0.1525 -0.016 1.5708 0 0.7854000000000001</pose>
      <inertial>
        <pose>0 0 0 0 0 0</pose>
        <mass>0.002</mass>
        <inertia>
          <ixx>1.9606856770000001e-08</ixx>
          <ixy>0</ixy>
          <ixz>0</ixz>
          <iyy>0.0030000000000000001</iyy>
          <iyz>0</iyz>
          <izz>0.0030000000000000001</izz>
        </inertia>
      </inertial>
      <collision name='propeller_collision'>
        <max_contacts>10</max_contacts>
        <pose>0 0 0 0 0 0</pose>
        <geometry>
          <mesh>
            <uri>propeller.stl</uri>
            <scale>1 1 1</scale>
          </mesh>
        </geometry>
      </collision>
      <visual name='propeller_visual'>
        <pose>0 0 0 0 0 0</pose>
        <geometry>
          <mesh>
            <uri>propeller.stl</uri>
            <scale>1 1 1</scale>
          </mesh>
        </geometry>
        <material>
          <shader type='pixel'/>
          <ambient>0 0.400000006 1 1</ambient>
          <diffuse>0 0.400000006 1 1</diffuse>
          <specular>0 0.400000006 1 1</specular>
          <emissive>0 0.400000006 1 1</emissive>
        </material>
        <transparency>0</transparency>
        <cast_shadows>false</cast_shadows>
      </visual>
    </link>
    <joint name='for_star_propeller_joint' type='revolute'>
      <parent>rov_body</parent>
      <child>for_star_propeller</child>
      <pose relative_to='for_star_propeller'>0 0 0 0 0 0</pose>
      <axis>
        <xyz>0 0 1</xyz>
        <limit>
          <lower>-inf</lower>
          <upper>inf</upper>
        </limit>
      </axis>
    </joint>
    <link name='for_port_propeller'>
      <pose>0.13500000000000001 -0.1525 -0.016 1.5708 0 -0.7854000000000001</pose>
      <inertial>
        <pose>0 0 0 0 0 0</pose>
        <mass>0.002</mass>
        <inertia>
          <ixx>1.9606856770000001e-08</ixx>
          <ixy>0</ixy>
          <ixz>0</ixz>
          <iyy>0.0030000000000000001</iyy>
          <iyz>0</iyz>
          <izz>0.0030000000000000001</izz>
        </inertia>
      </inertial>
      <collision name='propeller_collision'>
        <max_contacts>10</max_contacts>
        <pose>0 0 0 0 0 0</pose>
        <geometry>
          <mesh>
            <uri>propeller.stl</uri>
            <scale>1 1 1</scale>
          </mesh>
        </geometry>
      </collision>
      <visual name='propeller_visual'>
        <pose>0 0 0 0 0 0</pose>
        <geometry>
          <mesh>
            <uri>propeller.stl</uri>
            <scale>1 1 1</scale>
          </mesh>
        </geometry>
        <material>
          <shader type='pixel'/>
          <ambient>0 0.400000006 1 1</ambient>
          <diffuse>0 0.400000006 1 1</diffuse>
          <specular>0 0.400000006 1 1</specular>
          <emissive>0 0.400000006 1 1</emissive>
        </material>
        <transparency>0</transparency>
        <cast_shadows>false</cast_shadows>
      </visual>
    </link>
    <joint name='for_port_propeller_joint' type='revolute'>
      <parent>rov_body</parent>
      <child>for_port_propeller</child>
      <pose relative_to='for_port_propeller'>0 0 0 0 0 0</pose>
      <axis>
        <xyz>0 0 1</xyz>
        <limit>
          <lower>-inf</lower>
          <upper>inf</upper>
        </limit>
      </axis>
    </joint>
    <link name='aft_star_propeller'>
      <pose>-0.13500000000000001 0.14699999999999999 -0.016 -1.5708 0 -0.7854000000000001</pose>
      <inertial>
        <pose>0 0 0 0 0 0</pose>
        <mass>0.002</mass>
        <inertia>
          <ixx>1.9606856770000001e-08</ixx>
          <ixy>0</ixy>
          <ixz>0</ixz>
          <iyy>0.0030000000000000001</iyy>
          <iyz>0</iyz>
          <izz>0.0030000000000000001</izz>
        </inertia>
      </inertial>
      <collision name='propeller_collision'>
        <max_contacts>10</max_contacts>
        <pose>0 0 0 0 0 0</pose>
        <geometry>
          <mesh>
            <uri>propeller.stl</uri>
            <scale>1 1 1</scale>
          </mesh>
        </geometry>
      </collision>
      <visual name='propeller_visual'>
        <pose>0 0 0 0 0 0</pose>
        <geometry>
          <mesh>
            <uri>propeller.stl</uri>
            <scale>1 1 1</scale>
          </mesh>
        </geometry>
        <material>
          <shader type='pixel'/>
          <ambient>0 0.400000006 1 1</ambient>
          <diffuse>0 0.400000006 1 1</diffuse>
          <specular>0 0.400000006 1 1</specular>
          <emissive>0 0.400000006 1 1</emissive>
        </material>
        <transparency>0</transparency>
        <cast_shadows>false</cast_shadows>
      </visual>
    </link>
    <joint name='aft_star_propeller_joint' type='revolute'>
      <parent>rov_body</parent>
      <child>aft_star_propeller</child>
      <pose relative_to='aft_star_propeller'>0 0 0 0 0 0</pose>
      <axis>
        <xyz>0 0 1</xyz>
        <limit>
          <lower>-inf</lower>
          <upper>inf</upper>
        </limit>
      </axis>
    </joint>
    <link name='aft_port_propeller'>
      <pose>0.13500000000000001 0.14699999999999999 -0.016 -1.5708 0 0.7854000000000001</pose>
      <inertial>
        <pose>0 0 0 0 0 0</pose>
        <mass>0.002</mass>
        <inertia>
          <ixx>1.9606856770000001e-08</ixx>
          <ixy>0</ixy>
          <ixz>0</ixz>
          <iyy>0.0030000000000000001</iyy>
          <iyz>0</iyz>
          <izz>0.0030000000000000001</izz>
        </inertia>
      </inertial>
      <collision name='propeller_collision'>
        <max_contacts>10</max_contacts>
        <pose>0 0 0 0 0 0</pose>
        <geometry>
          <mesh>
            <uri>propeller.stl</uri>
            <scale>1 1 1</scale>
          </mesh>
        </geometry>
      </collision>
      <visual name='propeller_visual'>
        <pose>0 0 0 0 0 0</pose>
        <geometry>
          <mesh>
            <uri>propeller.stl</uri>
            <scale>1 1 1</scale>
          </mesh>
        </geometry>
        <material>
          <shader type='pixel'/>
          <ambient>0 0.400000006 1 1</ambient>
          <diffuse>0 0.400000006 1 1</diffuse>
          <specular>0 0.400000006 1 1</specular>
          <emissive>0 0.400000006 1 1</emissive>
        </material>
        <transparency>0</transparency>
        <cast_shadows>false</cast_shadows>
      </visual>
    </link>
    <joint name='aft_port_propeller_joint' type='revolute'>
      <parent>rov_body</parent>
      <child>aft_port_propeller</child>
      <pose relative_to='aft_port_propeller'>0 0 0 0 0 0</pose>
      <axis>
        <xyz>0 0 1</xyz>
        <limit>
          <lower>-inf</lower>
          <upper>inf</upper>
        </limit>
      </axis>
    </joint>
    <link name='star_top_propeller'>
      <pose>-0.185 -0.0031250000000000002 0.030624999999999999 0 0 0</pose>
      <inertial>
        <pose>0 0 0 0 0 0</pose>
        <mass>0.002</mass>
        <inertia>
          <ixx>1.9606856770000001e-08</ixx>
          <ixy>0</ixy>
          <ixz>0</ixz>
          <iyy>0.0030000000000000001</iyy>
          <iyz>0</iyz>
          <izz>0.0030000000000000001</izz>
        </inertia>
      </inertial>
      <collision name='propeller_collision'>
        <max_contacts>10</max_contacts>
        <pose>0 0 0 0 0 0</pose>
        <geometry>
          <mesh>
            <uri>propeller.stl</uri>
            <scale>1 1 1</scale>
          </mesh>
        </geometry>
      </collision>
      <visual name='propeller_visual'>
        <pose>0 0 0 0 0 0</pose>
        <geometry>
          <mesh>
            <uri>propeller.stl</uri>
            <scale>1 1 1</scale>
          </mesh>
        </geometry>
        <material>
          <shader type='pixel'/>
          <ambient>0 0.400000006 1 1</ambient>
          <diffuse>0 0.400000006 1 1</diffuse>
          <specular>0 0.400000006 1 1</specular>
          <emissive>0 0.400000006 1 1</emissive>
        </material>
        <transparency>0</transparency>
        <cast_shadows>false</cast_shadows>
      </visual>
    </link>
    <joint name='star_top_propeller_joint' type='revolute'>
      <parent>rov_body</parent>
      <child>star_top_propeller</child>
      <pose relative_to='star_top_propeller'>0 0 0 0 0 0</pose>
      <axis>
        <xyz>0 0 1</xyz>
        <limit>
          <lower>-inf</lower>
          <upper>inf</upper>
        </limit>
      </axis>
    </joint>
    <link name='port_top_propeller'>
      <pose>0.185 -0.0031250000000000002 0.030624999999999999 0 0 0</pose>
      <inertial>
        <pose>0 0 0 0 0 0</pose>
        <mass>0.002</mass>
        <inertia>
          <ixx>1.9606856770000001e-08</ixx>
          <ixy>0</ixy>
          <ixz>0</ixz>
          <iyy>0.0030000000000000001</iyy>
          <iyz>0</iyz>
          <izz>0.0030000000000000001</izz>
        </inertia>
      </inertial>
      <collision name='propeller_collision'>
        <max_contacts>10</max_contacts>
        <pose>0 0 0 0 0 0</pose>
        <geometry>
          <mesh>
            <uri>propeller.stl</uri>
            <scale>1 1 1</scale>
          </mesh>
        </geometry>
      </collision>
      <visual name='propeller_visual'>
        <pose>0 0 0 0 0 0</pose>
        <geometry>
          <mesh>
            <uri>propeller.stl</uri>
            <scale>1 1 1</scale>
          </mesh>
        </geometry>
        <material>
          <shader type='pixel'/>
          <ambient>0 0.400000006 1 1</ambient>
          <diffuse>0 0.400000006 1 1</diffuse>
          <specular>0 0.400000006 1 1</specular>
          <emissive>0 0.400000006 1 1</emissive>
        </material>
        <transparency>0</transparency>
        <cast_shadows>false</cast_shadows>
      </visual>
    </link>
    <joint name='port_top_propeller_joint' type='revolute'>
      <parent>rov_body</parent>
      <child>port_top_propeller</child>
      <pose relative_to='port_top_propeller'>0 0 0 0 0 0</pose>
      <axis>
        <xyz>0 0 1</xyz>
        <limit>
          <lower>-inf</lower>
          <upper>inf</upper>
        </limit>
      </axis>
    </joint>
    <link name='front_camera_enclosure'>
      <pose>0 -0.20000000000000001 -0.025000000000000001 0 1.5707963009853283 0</pose>
      <inertial>
        <pose>0 0 0 0 0 0</pose>
        <mass>1.0600000000000001</mass>
      </inertial>
      <collision name='front_camera_enclosure_collision'>
        <geometry>
          <cylinder>
            <radius>0.025000000000000001</radius>
            <length>0.14999999999999999</length>
          </cylinder>
        </geometry>
      </collision>
      <visual name='front_camera_enclosure_visual'>
        <geometry>
          <cylinder>
            <radius>0.025000000000000001</radius>
            <length>0.14999999999999999</length>
          </cylinder>
        </geometry>
        <material>
          <ambient>0 0 1 1</ambient>
          <diffuse>0 0 1 1</diffuse>
          <specular>0 0 1 1</specular>
          <emissive>0 0 0 1</emissive>
        </material>
        <transparency>0.40000000000000002</transparency>
        <cast_shadows>false</cast_shadows>
      </visual>
    </link>
    <joint name='front_camera_enclosure_joint' type='fixed'>
      <parent>rov_body</parent>
      <child>front_camera_enclosure</child>
      <pose>0 0 0 0 0 0</pose>
    </joint>
    <link name='front_camera_forward'>
      <pose relative_to='front_camera_enclosure'>0 -0.0050000000000000001 0 0 0 0</pose>
      <inertial>
        <mass>0.001</mass>
      </inertial>
      <collision name='front_camera_forward_collision'>
        <geometry>
          <box>
            <size>0.01 0.01 0.01</size>
          </box>
        </geometry>
      </collision>
      <visual name='front_camera_forward_visual'>
        <geometry>
          <box>
            <size>0.01 0.01 0.01</size>
          </box>
        </geometry>
        <cast_shadows>false</cast_shadows>
      </visual>
      <sensor name='front_camera_sensor' type='camera'>
        <pose relative_to='front_camera_forward'>0 0 0 1.5708 5.5511151231257827e-17 -1.5708</pose>
        <camera>
          <horizontal_fov>2.0943999999999998</horizontal_fov>
          <image>
            <width>320</width>
            <height>240</height>
          </image>
          <clip>
            <near>0.001</near>
            <far>100</far>
          </clip>
          <vertical_fov>1.171</vertical_fov>
        </camera>
        <always_on>true</always_on>
        <update_rate>30</update_rate>
        <visualize>true</visualize>
        <topic>front_camera_forward</topic>
      </sensor>
    </link>
    <joint name='front_camera_forward_joint' type='revolute'>
      <parent>front_camera_enclosure</parent>
      <child>front_camera_forward</child>
      <pose relative_to='front_camera_enclosure'>0 0 0 0 0 0</pose>
      <axis>
        <xyz>0 0 1</xyz>
        <limit>
          <lower>-inf</lower>
          <upper>inf</upper>
        </limit>
      </axis>
    </joint>
    <link name='front_camera_downtilt'>
      <pose relative_to='front_camera_enclosure'>0.02 -0.0050000000000000001 0 0 0 -1.1693700000000002</pose>
      <inertial>
        <mass>0.001</mass>
      </inertial>
      <collision name='front_camera_downtilt_collision'>
        <geometry>
          <box>
            <size>0.01 0.01 0.01</size>
          </box>
        </geometry>
      </collision>
      <visual name='front_camera_downtilt_visual'>
        <geometry>
          <box>
            <size>0.01 0.01 0.01</size>
          </box>
        </geometry>
        <cast_shadows>false</cast_shadows>
      </visual>
      <sensor name='front_camera_sensor' type='camera'>
        <pose relative_to='front_camera_downtilt'>0 0 0 1.5708 0 0</pose>
        <camera>
          <horizontal_fov>2.0943999999999998</horizontal_fov>
          <image>
            <width>320</width>
            <height>240</height>
          </image>
          <clip>
            <near>0.001</near>
            <far>100</far>
          </clip>
          <vertical_fov>1.171</vertical_fov>
        </camera>
        <always_on>true</always_on>
        <update_rate>30</update_rate>
        <visualize>true</visualize>
        <topic>front_camera_downtilt</topic>
      </sensor>
    </link>
    <joint name='front_camera_downtilt_joint' type='revolute'>
      <parent>front_camera_enclosure</parent>
      <child>front_camera_downtilt</child>
      <pose relative_to='front_camera_enclosure'>0 0 0 0 0 0</pose>
      <axis>
        <xyz>0 0 1</xyz>
        <limit>
          <lower>-inf</lower>
          <upper>inf</upper>
        </limit>
      </axis>
    </joint>
    <link name='back_camera_enclosure'>
      <pose>0 0.20000000000000001 -0.025000000000000001 0 1.5707963009853283 0</pose>
      <inertial>
        <pose>0 0 0 0 0 0</pose>
        <mass>1.0600000000000001</mass>
      </inertial>
      <collision name='back_camera_enclosure_collision'>
        <geometry>
          <cylinder>
            <radius>0.025000000000000001</radius>
            <length>0.14999999999999999</length>
          </cylinder>
        </geometry>
      </collision>
      <visual name='back_camera_enclosure_visual'>
        <geometry>
          <cylinder>
            <radius>0.025000000000000001</radius>
            <length>0.14999999999999999</length>
          </cylinder>
        </geometry>
        <material>
          <ambient>0 0 1 1</ambient>
          <diffuse>0 0 1 1</diffuse>
          <specular>0 0 1 1</specular>
          <emissive>0 0 0 1</emissive>
        </material>
        <transparency>0.40000000000000002</transparency>
        <cast_shadows>false</cast_shadows>
      </visual>
    </link>
    <joint name='back_camera_enclosure_joint' type='fixed'>
      <parent>rov_body</parent>
      <child>back_camera_enclosure</child>
      <pose>0 0 0 0 0 0</pose>
    </joint>
    <link name='back_camera_forward'>
      <pose relative_to='back_camera_enclosure'>0 0.0050000000000000001 0 0 0 0</pose>
      <inertial>
        <mass>0.001</mass>
      </inertial>
      <collision name='back_camera_forward_collision'>
        <geometry>
          <box>
            <size>0.01 0.01 0.01</size>
          </box>
        </geometry>
      </collision>
      <visual name='back_camera_forward_visual'>
        <geometry>
          <box>
            <size>0.01 0.01 0.01</size>
          </box>
        </geometry>
        <cast_shadows>false</cast_shadows>
      </visual>
      <sensor name='back_camera_sensor' type='camera'>
        <pose relative_to='back_camera_forward'>0 0 0 -1.5708 5.5511151231257827e-17 1.5708</pose>
        <camera>
          <horizontal_fov>2.0943999999999998</horizontal_fov>
          <image>
            <width>320</width>
            <height>240</height>
          </image>
          <clip>
            <near>0.001</near>
            <far>100</far>
          </clip>
          <vertical_fov>1.171</vertical_fov>
        </camera>
        <always_on>true</always_on>
        <update_rate>30</update_rate>
        <visualize>true</visualize>
        <topic>back_camera_forward</topic>
      </sensor>
    </link>
    <joint name='back_camera_forward_joint' type='revolute'>
      <parent>back_camera_enclosure</parent>
      <child>back_camera_forward</child>
      <pose relative_to='back_camera_enclosure'>0 0 0 0 0 0</pose>
      <axis>
        <xyz>0 0 1</xyz>
        <limit>
          <lower>-inf</lower>
          <upper>inf</upper>
        </limit>
      </axis>
    </joint>
    <link name='back_camera_downtilt'>
      <pose relative_to='back_camera_enclosure'>0.02 0.0050000000000000001 0 0 0 -1.1693700000000002</pose>
      <inertial>
        <mass>0.001</mass>
      </inertial>
      <collision name='back_camera_downtilt_collision'>
        <geometry>
          <box>
            <size>0.01 0.01 0.01</size>
          </box>
        </geometry>
      </collision>
      <visual name='back_camera_downtilt_visual'>
        <geometry>
          <box>
            <size>0.01 0.01 0.01</size>
          </box>
        </geometry>
        <cast_shadows>false</cast_shadows>
      </visual>
      <sensor name='back_camera_sensor' type='camera'>
        <pose relative_to='back_camera_downtilt'>0 0 0 -1.5708 5.5511151231257827e-17 1.5708</pose>
        <camera>
          <horizontal_fov>2.0943999999999998</horizontal_fov>
          <image>
            <width>320</width>
            <height>240</height>
          </image>
          <clip>
            <near>0.001</near>
            <far>100</far>
          </clip>
          <vertical_fov>1.171</vertical_fov>
        </camera>
        <always_on>true</always_on>
        <update_rate>30</update_rate>
        <visualize>true</visualize>
        <topic>back_camera_downtilt</topic>
      </sensor>
    </link>
    <joint name='back_camera_downtilt_joint' type='revolute'>
      <parent>back_camera_enclosure</parent>
      <child>back_camera_downtilt</child>
      <pose relative_to='back_camera_enclosure'>0 0 0 0 0 0</pose>
      <axis>
        <xyz>0 0 1</xyz>
        <limit>
          <lower>-inf</lower>
          <upper>inf</upper>
        </limit>
      </axis>
    </joint>
    <plugin name='gz::sim::systems::EER_Hydrodynamics' filename='plugins/libEER_Hydrodynamics.so'>
      <link_name>rov_body</link_name>
      <water_density>1000</water_density>
      <xDotU>1.32246275</xDotU>
      <yDotV>1.04396026</yDotV>
      <zDotW>6.64814797</zDotW>
      <kDotP>0.03548512</kDotP>
      <mDotQ>0.02818614</mDotQ>
      <nDotR>0.01814365</nDotR>
      <xUabsU>-40</xUabsU>
      <xU>-30</xU>
      <yVabsV>-40</yVabsV>
      <yV>-25</yV>
      <zWabsW>-50</zWabsW>
      <zW>-50</zW>
      <kPabsP>-20</kPabsP>
      <kP>-20</kP>
      <mQabsQ>-125</mQabsQ>
      <mQ>-50</mQ>
      <nRabsR>-20</nRabsR>
      <nR>-20</nR>
    </plugin>
    <plugin name='gz::sim::systems::EER_Thruster' filename='plugins/libEER_Thruster.so'>
      <namespace>waterwitch</namespace>
      <joint_name>for_star_propeller_joint</joint_name>
      <use_esc_cmd>true</use_esc_cmd>
      <fluid_density>1000</fluid_density>
      <topic>for_star</topic>
      <propeller_diameter>0.076</propeller_diameter>
    </plugin>
    <plugin name='gz::sim::systems::EER_Thruster' filename='plugins/libEER_Thruster.so'>
      <namespace>waterwitch</namespace>
      <joint_name>for_port_propeller_joint</joint_name>
      <use_esc_cmd>true</use_esc_cmd>
      <fluid_density>1000</fluid_density>
      <topic>for_port</topic>
      <propeller_diameter>0.076</propeller_diameter>
    </plugin>
    <plugin name='gz::sim::systems::EER_Thruster' filename='plugins/libEER_Thruster.so'>
      <namespace>waterwitch</namespace>
      <joint_name>aft_star_propeller_joint</joint_name>
      <use_esc_cmd>true</use_esc_cmd>
      <fluid_density>1000</fluid_density>
      <topic>aft_star</topic>
      <propeller_diameter>0.076</propeller_diameter>
    </plugin>
    <plugin name='gz::sim::systems::EER_Thruster' filename='plugins/libEER_Thruster.so'>
      <namespace>waterwitch</namespace>
      <joint_name>aft_port_propeller_joint</joint_name>
      <use_esc_cmd>true</use_esc_cmd>
      <fluid_density>1000</fluid_density>
      <topic>aft_port</topic>
      <propeller_diameter>0.076</propeller_diameter>
    </plugin>
    <plugin name='gz::sim::systems::EER_Thruster' filename='plugins/libEER_Thruster.so'>
      <namespace>waterwitch</namespace>
      <joint_name>star_top_propeller_joint</joint_name>
      <use_esc_cmd>true</use_esc_cmd>
      <fluid_density>1000</fluid_density>
      <topic>star_top</topic>
      <propeller_diameter>0.076</propeller_diameter>
    </plugin>
    <plugin name='gz::sim::systems::EER_Thruster' filename='plugins/libEER_Thruster.so'>
      <namespace>waterwitch</namespace>
      <joint_name>port_top_propeller_joint</joint_name>
      <use_esc_cmd>true</use_esc_cmd>
      <fluid_density>1000</fluid_density>
      <topic>port_top</topic>
      <propeller_diameter>0.076</propeller_diameter>
    </plugin>
    <plugin name='gz::sim::systems::Servo' filename='plugins/libEER_Servo.so'>
      <joint>front_camera_forward_joint</joint>
      <topic>front_camera_forward_servo</topic>
    </plugin>
    <plugin name='gz::sim::systems::Servo' filename='plugins/libEER_Servo.so'>
      <joint>front_camera_downtilt_joint</joint>
      <topic>front_camera_downtilt_servo</topic>
    </plugin>
    <plugin name='gz::sim::systems::Servo' filename='plugins/libEER_Servo.so'>
      <joint>back_camera_forward_joint</joint>
      <topic>back_camera_forward_servo</topic>
    </plugin>
    <plugin name='gz::sim::systems::Servo' filename='plugins/libEER_Servo.so'>
      <joint>back_camera_downtilt_joint</joint>
      <topic>back_camera_downtilt_servo</topic>
    </plugin>
    <static>false</static>
    <self_collide>false</self_collide>
    <allow_auto_disable>true</allow_auto_disable>
    <pose>1 1 1 1.0000000000000002 1.0000000000000002 1.0000000000000002</pose>
  </model>
</sdf>
